Workbook

Sheet Formato Syllabus
C2: FORMATO | I2: Versión: 0
I3: Código: IAC-201-f1
B4: SYLLABUS | I4: Fecha:16/Sep/2025
B6: 1. Información General de la Unidad de Estudio
B7: Año | D7: Código Plan de estudios | F7: Código Unidad de Estudio | H7: Tipo Unidad de estudio
B8: Facultad o Área | D8: Programa | G8: Nombre Unidad de estudios
B9: Créditos Académicos | D9: HAD | F9: HTA | H9: HT | I9: =E9+G9 -> 0
B10: 2. Modalidad y Metodología
B11: Seleccione con una X la modalidad en la que se desarrolla la Unidad. | D11: Presencial | G11: Virtual
B13: Metodología (Aplica solo para unidades de estudio de la modalidad presencial)
B14: PAT | E14: In Situ | G14: Híbrida
B15: 3. Propósito, Competencias y Resultados de Aprendizaje.
B16: Propósito de la Unidad de Estudio
B18: Competencia de Programa
B19: Resultado de Aprendizaje de Programa
B21: Resultado de Aprendizaje Unidad de Estudio
B23: Criterios de evaluación | D23: 1.
D24: 2.
D25: 3.
D26: 4.
B27: Competencias del modelo educativo a desarrollar (Seleccione con X aquellas competencias del modelo educativo que se desarrollarán en la Unidad de Estudio). | D27: EM | F27: SH | H27: IN
D28: COM | F28: SO | H28: AA
D29: SE | F29: COL | H29: DI
B30: *Las competencias corresponden a: EM: Emprendedoras, SH: Socio-humanísticas, IN: Investigativas, COM: Comunicativas, SO: Sostenibilidad, AA: Aprendizaje Autónomo, SE: Socio Emocionales, COL: Colaborativas, DI: Digitales.
B35: 4. Contenidos y Estrategias Pedagógicas
B36: En este apartado se solicita diligenciar los temas que harán parte de los contenidos de la UE; En cuanto a las estrategias pedagógicas relacionar los métodos, técnicas o acciones planificadas que se utilizan para facilitar el proceso de enseñanza-aprendizaje.
B39: Contenidos Unidad de estudio: | F39: Estrategias Pedagógicas:
B48: 5. Esquema de Calificación, Recursos y Componente de Lengua Extranjera
B49: Esquema de Calificación: (Asignación puntajes, notas y ponderación que tienen las actividades desarrolladas en la Unidad de Estudio). | F49: Recursos Tecnológicos
B60: Componente de Lengua extranjera | H60: Porcentaje
B65: 6. Bibliografía Obligatoria y Complementaria.
B66: Bibliografía Obligatoria | F66: Bibliografía Complementaria
B81: 7. Control de Cambios
B82: # versión | C82: Fecha | D82: Elaoró | E82: Revisó | F82: Aprobó | G82: Descripción del cambio

Sheet Formato Syllabus_NV
C2: FORMATO | I2: Versión: 0
I3: Código: IAC-201-f1
B4: SYLLABUS | I4: Fecha:16/Sep/2025
B6: 1. Información General de la Unidad de Estudio
B7: Año | D7: Código Plan de estudios | F7: Código Unidad de Estudio | H7: Tipo Unidad de estudio
B8: Facultad o Área | D8: Programas | G8: Nombre Unidad de estudios | K8: Agrehar posgrado pregrado
B9: Créditos Académicos | C9: 3 | D9: HAD | E9: 54 | F9: HTA | G9: 90 | H9: HT | I9: =E9+G9 -> 144 | K9: Tenr claro quienes van a responder por esas coordinaciones
B10: 2. Modalidad y Metodología
B11: Seleccione con una X la modalidad en la que se desarrolla la Unidad. | D11: Presencial | G11: Virtual
B13: Metodología (Aplica solo para unidades de estudio de la modalidad presencial)
B14: PAT | E14: In Situ | G14: Híbrida
B15: 3. Propósito, Competencias y Resultados de Aprendizaje.
B16: Propósito de la Unidad de Estudio | D16: descripción delcurso
B18: Competencia de Programa
B19: Resultado de Aprendizaje de Programa
B21: Resultado de Aprendizaje Unidad de Estudio | D21: matriz
B23: Criterios de evaluación | D23: 1.
D24: 2.
D25: 3.
D26: 4.
B27: Competencias del modelo educativo a desarrollar alinear como casilla y dejar descripción pie de pagina | D27: Emprendimiento Sostenible | G27: Liderar procesos emprendedores e innovadores para crear o transformar organizaciones y entornos hacia la sostenibilidad, generando valor en contextos diversos e inciertos. | L27: cargar los ysllabus de cinco años anteriores
D28: Power Humanise | G28: Integrar pensamiento crítico, empatía, diseño centrado en las personas y criterios éticos y sostenibles para crear soluciones, relaciones y acciones que promuevan bienestar, propósito y valor colectivo. | L28: Oferta actual a 2026 - 1
D29: TECH IA MAKER | G29: Utilizar la IA de manera ética, crítica y estratégica para potenciar capacidades humanas, resolver problemas, crear soluciones, optimizar procesos y generar valor. | L29: Solicitar a los profesores comité curricular antes
B30: 4. Contenidos y Estrategias Pedagógicas
B31: En este apartado se solicita diligenciar los temas que harán parte de los contenidos de la UE; En cuanto a las estrategias pedagógicas relacionar los métodos, técnicas o acciones planificadas que se utilizan para facilitar el proceso de enseñanza-aprendizaje.
B34: Contenidos Unidad de estudio: dar tipologia 4.5 semanas, 9 semanas y 18 semanas | F34: Estrategias Pedagógicas:
B43: 5. Esquema de Calificación, Recursos y Componente de Lengua Extranjera
B44: Esquema de Calificación: (Asignación puntajes, notas y ponderación que tienen las actividades desarrolladas en la Unidad de Estudio). Redactar en evaluación de impacto, meter con las competencia emprendimiento sostebible, power humanise o ia tech maker | F44: Recursos Tecnológicos reorganizar
B55: Componente de Lengua extranjera solo inglés | F55: Inglés | H55: Porcentaje
B60: 6. Bibliografía Obligatoria y Complementaria.
B61: Bibliografía Obligatoria | F61: Bibliografía Complementaria
B76: 7. Control de Cambios
B77: # versión | C77: Fecha | D77: Elaoró | E77: Revisó | F77: Aprobó | G77: Descripción del cambio

Sheet Data
A1: Llave | B1: AÑO | C1: Código Plan de estudios | D1: Código Unidad de Estudio | E1: Tipo Unidad de estudio | F1: Facultad o Área | G1: Programa | H1: Nombre Unidad de estudios | I1: Créditos Académicos | J1: HAD | K1: HTA | L1: HT | M1: Presencial | N1: Virtual | O1: PAT | P1: In Situ | Q1: Híbrida | R1: Propósito de la Unidad de Estudio | S1: Competencia de Programa | T1: Resultado de Aprendizaje de Programa | U1: Resultado de Aprendizaje Unidad de Estudio | V1: 1. | W1: 2. | X1: 3. | Y1: 4. | Z1: EM | AA1: SH | AB1: IN | AC1: CO | AD1: SO | AE1: AU | AF1: SE | AG1: COL | AH1: DI | AI1: Contenidos Unidad de estudio: | AJ1: Estrategias Pedagógicas: | AK1: Esquema de Calificación: | AL1: Recursos Tecnológicos | AM1: Componente de Lengua extranjera | AN1: Porcentaje | AO1: Bibliografía Obligatoria | AP1: Bibliografia Complementaria
A2: =G2&H2 -> MERCADEOIDIOMA I | B2: 2023 | C2: 2000242 | D2: VFV00001 | E2: TRANSVERSALES SERVICIO PREGRADO VIRTUAL | F2: FAFCE | G2: MERCADEO | H2: IDIOMA I | I2: 3 | J2: =+L2-K2 -> 48 | K2: 144 | L2: 192 | N2: VIRTUAL | S2: Interpretar datos de mercado y de los consumidores teniendo en cuenta metodologías de análisis, eficacia y rentabilidad empresarial siendo coherentes con los objetivos de la organización. Desarrollar estrategias de mercadeo integrales con base en en el análisis de mercado, tendencias, y comportamiento del consumidor para una mayor visibilidad y posicionamiento de las marcas en entornos competitivos. Diseñar estrategias de branding y creación de marcas con propósito a través de la generación de contenido atractivo que resuene con diversas audiencias y se alinee con los principios de mercadeo sostenible. Aplicar el pensamiento creativo e innovador en el desarrollo de estrategias de mercadeo mediante campañas publicitarias originales, productos innovadores, y estrategias disruptivas, con segmentación de audiencias y alianzas estratégicas para el éxito empresarial. | T2: Analiza datos de mercado y comportamiento de los consumidores a partir del uso de metodologías, lineamientos de eficacia y rentabilidad, enfocados en los objetivos organizacionales. Formula estrategias basadas en la comprensión del mercado mediante el estudio del mercado para el posicionamiento y reconocimiento de las marcas. Diseña marcas con propósito y planes de comunicación con base en en las diferentes audiencias teniendo en cuenta los principios de sostenibilidad. Desarrolla campañas publicitarias, productos innovadores y estrategias disruptivas con base en el crecimiento organizacional del mercado a partir de la creación de alianzas estratégicas, la segmentación de audiencias y el pensamiento creativo e innovador. Integra principios éticos sostenibles y de responsabilidad social en las estrategias de mercadeo teniendo en cuenta la proposición de acciones encaminadas a la creación de valor compartido y la integridad organizacional. Planifica el desarrollo de sitios web y aplicaciones digitales a través del uso de herramientas y técnicas avanzadas de diseño y desarrollo web | V2: Oral production: Can give simple descriptions and presentations with appropriate highlighting of significant points. | W2: Written production: Can write clear texts on subjects related to work, study, nature, and food | X2: Oral interaction: Can interact with some confidence on familiar routines provided time to prepare is given. | Y2: Written interaction: Can post a comprehensible contribution in anonline discussion on a familiar topic of interest, if he/she can prepare the text beforehand and use online tools to fill gaps in language and check accuracy. | AA2: X | AC2: X | AE2: X | AF2: X | AG2: X | AH2: X | AI2: Reasoning, analysis and summarizing • Self-planning, arranging and evaluating • Grouping, associating and imagery • Guessing and switching to L1 • Using music, laughter or meditation • Understanding other points of view • Self-management, self-monitoring and self-evaluation • Cooperation | AO2: Cambridge Dictionary. (2023). Cambridge dictionary online . Cambridge Dictionary.
A3: =G3&H3 -> MERCADEOIDIOMA II | B3: 2023 | C3: 2000242 | D3: VFV00002 | E3: TRANSVERSALES SERVICIO PREGRADO VIRTUAL | F3: FAFCE | G3: MERCADEO | H3: IDIOMA II | I3: 4 | J3: =+L3-K3 -> 48 | K3: 144 | L3: 192 | N3: VIRTUAL | R3: IDIOMA II is a course that has been designed to provide students with the necessary tools to incorporate into their own knowledge the linguistic competence to appropriately communicate at an Intermediate level. In this level, students will apply general previous knowledge in conversations and written texts in which they will provide and exchange information related to business topics. | S3: Interpretar datos de mercado y de los consumidores teniendo en cuenta metodologías de análisis, eficacia y rentabilidad empresarial siendo coherentes con los objetivos de la organización. Desarrollar estrategias de mercadeo integrales con base en en el análisis de mercado, tendencias, y comportamiento del consumidor para una mayor visibilidad y posicionamiento de las marcas en entornos competitivos. Diseñar estrategias de branding y creación de marcas con propósito a través de la generación de contenido atractivo que resuene con diversas audiencias y se alinee con los principios de mercadeo sostenible. Aplicar el pensamiento creativo e innovador en el desarrollo de estrategias de mercadeo mediante campañas publicitarias originales, productos innovadores, y estrategias disruptivas, con segmentación de audiencias y alianzas estratégicas para el éxito empresarial. | T3: Analiza datos de mercado y comportamiento de los consumidores a partir del uso de metodologías, lineamientos de eficacia y rentabilidad, enfocados en los objetivos organizacionales. Formula estrategias basadas en la comprensión del mercado mediante el estudio del mercado para el posicionamiento y reconocimiento de las marcas. Diseña marcas con propósito y planes de comunicación con base en en las diferentes audiencias teniendo en cuenta los principios de sostenibilidad. Desarrolla campañas publicitarias, productos innovadores y estrategias disruptivas con base en el crecimiento organizacional del mercado a partir de la creación de alianzas estratégicas, la segmentación de audiencias y el pensamiento creativo e innovador. Integra principios éticos sostenibles y de responsabilidad social en las estrategias de mercadeo teniendo en cuenta la proposición de acciones encaminadas a la creación de valor compartido y la integridad organizacional. Planifica el desarrollo de sitios web y aplicaciones digitales a través del uso de herramientas y técnicas avanzadas de diseño y desarrollo web | U3: Proficiently demonstrates command of the English language under the CEFR standards with a B1 level in the skills of listening comprehension, oral production, reading comprehension and written production in sociocultural, organizational and technological contexts of a formal and informal nature within an ethical, humanistic, investigative and sustainable framework. | V3: Develop effective communicative strategies to communicate in a business context at an A2+/B1 level. | W3: Elaborate expository and argumentative written texts with a suitable structure according to the level. | X3: Integrate basic communicative functions in spoken oral interaction for an effective exchange of ideas. | Y3: Plan on the use of communicative strategies as well as technological resources effectively. | Z3: X | AA3: X | AB3: X | AC3: X | AD3: X | AE3: X | AF3: X | AG3: X | AH3: X | AI3: Personality types Question formation Describing the present Narrating a biography Linking past and present events Describing one’s job Writing a cover letter Describing jobs and workplaces Discussing education Basic formal writing conventions Describing an advertising campaign Writing an opinion essay Hypothetising on the promotion of a product | AJ3: Online activities for autonomous practice Online Learning Objects in the Learning Environment Assignment of activities and tests in MyEnglishLab Group interactions in tutoring sessions Writing workshops in tutoring sessions Written and oral comprehension challenges in tutoring sessions Vocabulary and grammar tasks challenges in tutoring sessions | AK3: Learning Guideline 1 (15%) Learning Guideline 2 (15%) Learning Guideline 3 (15%) Discussion Forum: Education (5%) MyEnglishLab Activities Units 1-6 (15%) MyEnglishLab Tests – Units 1-6 (10%) Final Meeting / Untimely Test (25%) | AL3: Learning Environment - Virtual Room Idioma II MyEnglishLab – direct Access from Canvas eText – New Language Leader Intermediate Suggested resources online | AM3: Inglés | AN3: 1 | AO3: Online Textbook: Cotton, D., Falvey, D., & Kent, S. (2013). New Language Leader Intermediate. Essex: Pearson Education Limited. Websites: Online Dictionaries: 1. The Free dictionary https://www.thefreedictionary.com/ 2. Cambridge dictionary https://dictionary.cambridge.org/es/ 3. Merriam Webster https://www.merriam-webster.com/ 4. Collins (diccionario español-inglés) https://diccionario.reverso.net/espanol-ingles/ 5. BusinessDictionary http://www.businessdictionary.com/ 6. allBusiness https://www.allbusiness.com/barrons_dictionary | AP3: Reference books: Hancock, M. (2005). English Pronunciation in Use Intermediate. Cambridge: Cambridge University Press. Mascull, B. (2010). Business Vocabulary in Use : Intermediate . Cambridge: Cambridge University Press. McCarthy, M. (2004). English Phrasal Verbs in Use. Cambridge: Cambridge University Press. McCarthy, M., & O'Dell, F. (2007). English idioms in use. Cambridge: Cambridge University Press. Pearson Education. (2007). Longman Business English dictionary. Essex: Longman. Raymond, M., & Smalzer, W. R. (2000). Grammar in Use Intermediate (Vol. 2nd). Cambridge: Cambridge University Press. Smalzer, W. R., & Murphy, R. (2003). Grammar in Use: workbook. Cambridge: Cambridge University Press. Free resources British Council 1. Intermediate grammar. Retrieved from http://learnenglishteens.britishcouncil.org/grammar/intermediate-grammar 2. Reading. Intermediate B1 level. Retrieved from http://learnenglishteens.britishcouncil.org/skills/reading/intermediate-b1-reading 3. Listening. Intermediate B1 level. Retrieved from http://learnenglishteens.britishcouncil.org/skills/listening/intermediate-b1-listening 4. Writing Intermediate B1 level. Retrieved from http://learnenglishteens.britishcouncil.org/skills/writing/intermediate-B1-writing ESL video.com Listening. Intermediate level https://www.eslvideo.com/quizzes_intermediate DATABASE RESOURCES (https://login.bdbiblioteca.universidadean.edu.co/) Ragan, M. (2009). Mental Health. Mental Health (ELL), 1–2. Retrieved from https://search-ebscohost-com.bdbiblioteca.universidadean.edu.co/login.aspx?direct=true&db=elr&AN=33514475&site=ell-live Leeming, S. J. (2009). Jane Goodall, 1934-. Jane Goodall (ELL), 1–3. Retrieved from https://search-ebscohost-
A4: =G4&H4 -> MERCADEOIDIOMA III | B4: 2022 | C4: 2000242 | D4: VFV00003 | E4: TRANSVERSALES SERVICIO PREGRADO VIRTUAL | F4: FAFCE | G4: MERCADEO | H4: IDIOMA III | I4: 4 | J4: =+L4-K4 -> 48 | K4: 144 | L4: 192 | N4: VIRTUAL | R4: The course aims to help students understand and get familiar with the IELTS exam format, structure and the strategies, so that, when taking the test, they can achieve the B1 level (or above) in the overall score, in accordance with the scale of the Common European Framework of Reference for Languages (CEFR). | S4: Interpretar datos de mercado y de los consumidores teniendo en cuenta metodologías de análisis, eficacia y rentabilidad empresarial siendo coherentes con los objetivos de la organización. Desarrollar estrategias de mercadeo integrales con base en en el análisis de mercado, tendencias, y comportamiento del consumidor para una mayor visibilidad y posicionamiento de las marcas en entornos competitivos. Diseñar estrategias de branding y creación de marcas con propósito a través de la generación de contenido atractivo que resuene con diversas audiencias y se alinee con los principios de mercadeo sostenible. Aplicar el pensamiento creativo e innovador en el desarrollo de estrategias de mercadeo mediante campañas publicitarias originales, productos innovadores, y estrategias disruptivas, con segmentación de audiencias y alianzas estratégicas para el éxito empresarial. | T4: Analiza datos de mercado y comportamiento de los consumidores a partir del uso de metodologías, lineamientos de eficacia y rentabilidad, enfocados en los objetivos organizacionales. Formula estrategias basadas en la comprensión del mercado mediante el estudio del mercado para el posicionamiento y reconocimiento de las marcas. Diseña marcas con propósito y planes de comunicación con base en en las diferentes audiencias teniendo en cuenta los principios de sostenibilidad. Desarrolla campañas publicitarias, productos innovadores y estrategias disruptivas con base en el crecimiento organizacional del mercado a partir de la creación de alianzas estratégicas, la segmentación de audiencias y el pensamiento creativo e innovador. Integra principios éticos sostenibles y de responsabilidad social en las estrategias de mercadeo teniendo en cuenta la proposición de acciones encaminadas a la creación de valor compartido y la integridad organizacional. Planifica el desarrollo de sitios web y aplicaciones digitales a través del uso de herramientas y técnicas avanzadas de diseño y desarrollo web | U4: Demonstrates proficient command of the English language under the CEFR standards with a scope of B1.1 in the skills of listening comprehension, oral production, reading comprehension and written production in sociocultural, organizational and technological contexts of a formal and informal nature within a ethical-humanistic and investigative and sustainable framework. | V4: Speaking: Students’ speaking performance matches the speaking assessment criteria of a band-5 in the IELTS test. | W4: Writing: students’ writing production matches the writing assessment criteria of a band-5 in the IELTS test. | X4: Reading: students’ reading comprehension skills matches the reading assessment criteria of a band-5 in the IELTS test. | Y4: Listening: students’ listening comprehension skills matches the listening assessment criteria of a band-5 in the IELTS test | Z4: X | AA4: X | AB4: X | AC4: X | AD4: X | AE4: X | AF4: X | AG4: X | AH4: X | AI4: Modules 1-10 of the textbook Expert IELTS 5 | AJ4: Reasoning, analysis and summarizing • Self-planning, arranging and evaluating • Grouping, associating and imagery • Guessing and switching to L1 • Using music, laughter or meditation • Understanding other points of view • Self-management, self-monitoring and selfevaluation • Cooperation | AK4: 1. A mock speaking test of the IELTS. 2. A mock writing test of the IELTS. 3. A mock reading test of the IELTS. 4. A mock listening test of the IELTS. 5. Assignments modules 1-10 6. Grammar and vocabulary assignments modules 1-10 7. Final IELTS test including the four papers. | AL4: My English Lab – Expert IELTS 5 activities and tests - Free resources online | AM4: Inglés | AN4: 1 | AO4: Boyd, E. (2017). Expert IELTS 5 Coursebook with Online Audio for MyEnglishLab Pin Code Pack. Pearson Education. | AP4: Other reference books: Hancock, M. (2005). English Pronunciation in Use Intermediate. Cambridge: Cambridge University Press. - Mascull, B. (2010). Business Vocabulary in Use: Intermediate. Cambridge: Cambridge University Press. -McCarthy, M. (2004). English Phrasal Verbs in Use. Cambridge: Cambridge University Press. -McCarthy, M., & O'Dell, F. (2007). English idioms in use. Cambridge: Cambridge University Press. -Pearson Education. (2007). Longman Business English dictionary. Essex: Longman. - Raymond, M., & Smalzer, W. R. (2000). Grammar in Use Intermediate (Vol. 2nd). Cambridge: Cambridge University Press. -Smalzer, W. R., & Murphy, R. (2003). Grammar in Use: workbook. Cambridge: Cambridge University Press. - Shakespeare, W. (2006). Hamlet Penguin Readers. Essex: Pearson Education Limited. EAN library suggested readers: -Alan Maley. He Knows too Much. Level 6. Cambridge University Press. -Penny Hancock. A Love for Life. Level 6. Cambridge University Press. -Rod Neilson. The Sugar Glider. Level 5. Cambridge University Press. -Stephen Bryant. Business and the Speed of Thought. Level 6. Penguin Readers. -Susan Fearn. Benetton. Jonathan Mantle. Level 5. Penguin Readers.
A5: =G5&H5 -> MERCADEOIDIOMA IV | B5: 2022 | C5: 2000242 | D5: VFV02067 | E5: TRANSVERSALES SERVICIO PREGRADO VIRTUAL | F5: FAFCE | G5: MERCADEO | H5: IDIOMA IV | I5: 4 | J5: 48 | K5: 144 | L5: 192 | N5: VIRTUAL | R5: Idioma IV provides students of English with opportunities to practice their communication skills. Course work focus particularly on communication accuracy (vocabulary, grammar) with a strong emphasis on autonomous learning. Based on the CEFR (B1.2) a student who passes this course can: • Can understand the main points of clear standard input on familiar matters regularly encountered in work, school, leisure, etc. • Can deal with most situations likely to arise whilst travelling in an area where the language is spoken. • Can produce simple connected text on topics which are familiar or of personal interest. • Can describe experiences and events, dreams, hopes and ambitions and briefly give reasons and explanations for opinions and plans • take messages communicating enquiries, explaining problems; • provide concrete information required in an interview/consultation (e.g. describe symptoms to a doctor) but does so with limited precision; • explain why something is a problem; summarise and give his or her opinion about a short story, article, talk, discussion, interview, or documentary and answer further questions of detail; • carry out a prepared interview, checking and confirming information, though he/she may occasionally have to ask for repetition if the other person´s response is rapid or extended; • describe how to do something, giving detailed instructions; • exchange accumulated factual information on familiar routine and non-routine matters within his/her field with some confidence. | S5: Interpretar datos de mercado y de los consumidores teniendo en cuenta metodologías de análisis, eficacia y rentabilidad empresarial siendo coherentes con los objetivos de la organización. Desarrollar estrategias de mercadeo integrales con base en en el análisis de mercado, tendencias, y comportamiento del consumidor para una mayor visibilidad y posicionamiento de las marcas en entornos competitivos. Diseñar estrategias de branding y creación de marcas con propósito a través de la generación de contenido atractivo que resuene con diversas audiencias y se alinee con los principios de mercadeo sostenible. Aplicar el pensamiento creativo e innovador en el desarrollo de estrategias de mercadeo mediante campañas publicitarias originales, productos innovadores, y estrategias disruptivas, con segmentación de audiencias y alianzas estratégicas para el éxito empresarial. | T5: Analiza datos de mercado y comportamiento de los consumidores a partir del uso de metodologías, lineamientos de eficacia y rentabilidad, enfocados en los objetivos organizacionales. Formula estrategias basadas en la comprensión del mercado mediante el estudio del mercado para el posicionamiento y reconocimiento de las marcas. Diseña marcas con propósito y planes de comunicación con base en en las diferentes audiencias teniendo en cuenta los principios de sostenibilidad. Desarrolla campañas publicitarias, productos innovadores y estrategias disruptivas con base en el crecimiento organizacional del mercado a partir de la creación de alianzas estratégicas, la segmentación de audiencias y el pensamiento creativo e innovador. Integra principios éticos sostenibles y de responsabilidad social en las estrategias de mercadeo teniendo en cuenta la proposición de acciones encaminadas a la creación de valor compartido y la integridad organizacional. Planifica el desarrollo de sitios web y aplicaciones digitales a través del uso de herramientas y técnicas avanzadas de diseño y desarrollo web | U5: Demuestra dominio de manera proficiente del idioma inglés bajo los estandáres del MCER con un alcance de B1.2 en las habilidades de comprensión auditiva, producción oral, comprensión lectora y producción escrita en contextos socioculturales, organizacionales y tecnológicos de carácter formal e informal dentro de un marco ético-humanístico e investigativo y sostenible. | V5: Recognize the most commonly used words and expressions relating to design, trends, arts, media, shopping, museums and money when reading and/or listening. | W5: Exchange information by asking and answering questions about the suggested topics. | X5: Show understanding of the modal verbs, passive voice, gerunds, and infinitives, reported speech, third conditional, and past modals while using it in the affirmative, negative, and interrogative. | Z5: X | AA5: X | AB5: X | AC5: X | AD5: X | AE5: X | AF5: X | AG5: X | AH5: X | AI5: Vocabulary about design, trends, arts, media, shopping, museums, money. Grammar contents: modal verbs, passive voice, gerunds, and infinitives, reported speech, third conditional, past modals. Reading and listening strategies and skills. Speaking skills: taking part in meetings, revision of expressions to agree and disagree. | AJ5: Dialogues Role plays Reading and comprehension activities Grammar exercises (textbook or other resources) Group discussions Writing of texts LMS activities Learning Objects Immersion contexts Field trips Interactive videos Gamification Flipped learning | AK5: Learning guidelines 2 40 points (20each) MyEnglishLab Assignments 20 points MyEnglishLab Tests 15 points Final Face-to-Face Session or Untimely Test 25 points | AL5: Cotton, D., Falvey, D. & Kent, S. (2013). New Language Leader Intermediate. MyEnglishLab. Essex. English online software at https://www.pearsonelt.com/myenglishlab.html | AM5: INGLÉS | AN5: 1 | AO5: Online Textbook: Cotton, D., Falvey, D., & Kent, S. (2013). New Language Leader Intermediate. Essex: Pearson Education Limited. Websites: Online Dictionaries: 1. The Free dictionary https://www.thefreedictionary.com/ 2. Cambridge dictionary https://dictionary.cambridge.org/es/ 3. Merriam Webster https://www.merriam-webster.com/ 4. Collins (diccionario español-inglés) https://diccionario.reverso.net/espanol-ingles/ 5. allBusiness https://www.allbusiness.com/barrons_dictionary 6. Financial Dictionary http://financial-dictionary.thefreedictionary.com/ Database Resources for Extra Practice: • Biscontini, T. V. (2010). Fertile Crescent. Fertile Crescent (ELL), 1. In database Read It! • Ragan, M. (2009). Budgeting. Budgeting (ELL), 1–2. In database Read It! • Posner, T. (2009). Michael Faraday, 1781- 1867. Michael Faraday (ELL), 1–2. In database Read It! • DeSalle, N. (2009). Issac Asimov, 1920-1992. Issac Asimov (ELL), 1–2. In database Read It! • Harmon, A. (2017). Identity Theft. Identity Theft (ELL), 1. In database Read It! | AP5: Reference books: Hancock, M. (2005). English Pronunciation in Use Intermediate. Cambridge: Cambridge University Press. Mascull, B. (2010). Business Vocabulary in Use: Intermediate. Cambridge: Cambridge University Press. McCarthy, M. (2004). English Phrasal Verbs in Use. Cambridge: Cambridge University Press. McCarthy, M., & O'Dell, F. (2007). English idioms in use. Cambridge: Cambridge University Press. Pearson Education. (2007). Longman Business English dictionary. Essex: Longman. Raymond, M., & Smalzer, W. R. (2000). Grammar in Use Intermediate (Vol. 2nd). Cambridge: Cambridge University Press. Smalzer, W. R., & Murphy, R. (2003). Grammar in Use: workbook. Cambridge: Cambridge University Press. Free resources British Council 1. Intermediate grammar. Retrieved from http://learnenglishteens.britishcouncil.org/gra mmar/intermediate-grammar
A6: =G6&H6 -> MERCADEO Y ESTRATEGIA COMERCIALMERCADEO Y GENERAC DE VALOR PARA NEG | B6: 2023 | C6: 2001327 | D6: AFVN0019 | E6: NUCLEAR | F6: FAFCE | G6: MERCADEO Y ESTRATEGIA COMERCIAL | H6: MERCADEO Y GENERAC DE VALOR PARA NEG | I6: 4 | J6: 54 | K6: 90 | L6: 144 | N6: VIRTUAL | R6: En un mundo en constante evolución, con la aparición de competidores innovadores, cambiantes tendencias de consumo, y la transformación de los canales de comunicación por las generaciones nativas digitales, las marcas se enfrentan al desafío de cómo dialogar con los consumidores y construir relaciones duraderas y beneficiosas. Este ambiente de aprendizaje llamado Mercadeo y Generación de Valor para los Negocios, busca equipar a los estudiantes de mercadeo, administración y negocios internacionales con una comprensión sólida de los principios fundamentales del marketing y las herramientas emergentes que permiten la creación de estrategias y planes centrados en el consumidor. Este ambiente de aprendizaje contribuye significativamente al perfil del graduado, proporcionando habilidades esenciales | S6: Interpretar datos de mercado y de los consumidores teniendo en cuenta metodologías de análisis, eficacia y rentabilidad empresarial siendo coherentes con los objetivos de la organización. Desarrollar estrategias de mercadeo integrales con base en en el análisis de mercado, tendencias, y comportamiento del consumidor para una mayor visibilidad y posicionamiento de las marcas en entornos competitivos. Diseñar estrategias de branding y creación de marcas con propósito a través de la generación de contenido atractivo que resuene con diversas audiencias y se alinee con los principios de mercadeo sostenible. Aplicar el pensamiento creativo e innovador en el desarrollo de estrategias de mercadeo mediante campañas publicitarias originales, productos innovadores, y estrategias disruptivas, con segmentación de audiencias y alianzas estratégicas para el éxito empresarial. | T6: Analiza datos de mercado y comportamiento de los consumidores a partir del uso de metodologías, lineamientos de eficacia y rentabilidad, enfocados en los objetivos organizacionales. Formula estrategias basadas en la comprensión del mercado mediante el estudio del mercado para el posicionamiento y reconocimiento de las marcas. Diseña marcas con propósito y planes de comunicación con base en en las diferentes audiencias teniendo en cuenta los principios de sostenibilidad. Desarrolla campañas publicitarias, productos innovadores y estrategias disruptivas con base en el crecimiento organizacional del mercado a partir de la creación de alianzas estratégicas, la segmentación de audiencias y el pensamiento creativo e innovador. Integra principios éticos sostenibles y de responsabilidad social en las estrategias de mercadeo teniendo en cuenta la proposición de acciones encaminadas a la creación de valor compartido y la integridad organizacional. Planifica el desarrollo de sitios web y aplicaciones digitales a través del uso de herramientas y técnicas avanzadas de diseño y desarrollo web | U6: Diseña y evalúa estrategias y planes de mercadeo abordando temas como segmentación de mercado, posicionamiento, desarrollo de productos, fijación de precios, distribución y promoción. | V6: Comprende los principios fundamentales del mercadeo y su relevancia en la creación, entrega y captura de valor en el contexto empresarial. | W6: Identifica y comprende las necesidades y comportamientos de los consumidores para crear estrategias de mercadeo efectivas. | X6: Aplica los conceptos de mercadeo en el diseño de estrategias que permitan el crecimiento y posicionamiento empresarial. | Y6: Utiliza la tecnología y las métricas para asegurar el éxito de las estrategias de mercadeo. | Z6: x | AA6: x | AB6: x | AC6: x | AD6: x | AE6: x | AF6: x | AG6: x | AH6: x | AI6: 1. Fundamentos del Mercadeo o Introducción al mercadeo y su rol en los negocios sostenibles. Las filosofías del mercadeo. El marketing Mix. o Tendencias de consumo. Los consumidores. Análisis del entorno. 2. Desarrollo de Productos y Estrategias de Precio o Estrategias de producto y desarrollo de productos o Estrategias de precios y valor percibido 3. Comunicación y Logística de Marketing o Promoción y comunicación de marketing o Canales de distribución y logística 4. Gestión de Marca e Introducción al Marketing Digital o Gestión de marca y construcción de relaciones con el cliente o Métricas de evaluación de las estrategias y planes de mercadeo | AJ6: • Aprendizaje Autónomo • Tutorías • Evaluación | AK6: Cuatro (4) cortes de evaluación  Actividad Primer Hito 20%  Actividad Segundo Hito 20%  Actividad Tercer Hito 20%  Actividad Cuarto Hito 20%  Encuentro Final 20% | AL6:  Aula plataforma Canvas  Uso de base de datos EMIS  Plataforma Cisco Webex  Paquete office de Microsoft | AM6: Inglés | AN6: 0.6 | AO6: Barón López, E. (2017). Fundamentos de Mercadeo. Benassini, M. (2014). Introducción a la investigación de mercados: un enfoque para América Latina. Pearson Educación. Tercera Edición. Briceño Ariza, L. (2016). Fundamentos de mercadeo: tendencias del mercado y comportamiento del consumidor Chaffey, D. y Ellis-Chadwick, F. (2014). Marketing Digital:: estrategia, implementación práctica. México: Pearson Design Counsil (2007), Eleven Lessons: Managing Design in Eleven Global Brands. A Study of the Design Process Kotler, P., Armstrong, G., Mues Zepeda, A., Costal Pérez, M. P., Cavazos Arroyo, J., & Aguirre Miling, H. (2013). Fundamentos de marketing. México: Pearson. Martin, D. M., & Schouten, J. (2011) Sustainable marketing (p. 264). Pearson Prentice Hall. | AP6: Arévalo Acosta, G. (2019-11.). Fundamentos de mercadeo. Cómo buscan el éxito las organizaciones. Bogotá: Fundación Universitaria del Área Andina, 2019. Botero Cardona, L. (2015). Evolución histórica del marketing Cateora, P. R., Gilly, M. C., & Graham, J. L. (2013). Marketing internacional. México. AMGH. Crane, F. G., Kerin, R. A., Hartley, S. W., Berkowitz, E. N., & Rudelius, W. (2014). Marketing. México: McGraw-Hill Interamerican. Kotler, P., Kartajaya, H., & Setiawan, I. (2011). Marketing 3.0: Cómo atraer a los clientes con un marketing basado en valores. Bogotá: Ediciones de la U. Lamb, C., Hair, J. and McDaniel, C. (2010). Marketing. México: Thomson. Loundon, D. & Della Bitta, A., (2010). Comportamiento del Consumidor. México: Mc Graw Hill. Stanton, W. (2007). Fundamentos de Marketing. México: Mc Graw Hill.
A7: =G7&H7 -> MERCADEO Y ESTRATEGIA COMERCIALDINERO Y FINANZAS | B7: 2022 | C7: 2001327 | D7: AFVN0025 | E7: NUCLEAR | F7: FAFCE | G7: MERCADEO Y ESTRATEGIA COMERCIAL | H7: DINERO Y FINANZAS | I7: 4 | J7: 72 | K7: 120 | L7: 192 | N7: VIRTUAL | R7: Los profesionales eanistas se caracterizan por su capacidad para tomar decisiones informadas, utilizando criterios claros y objetivos. Para que esta toma de decisiones sea eficiente, se deben considerar todos los posibles efectos que pueden generar, incluyendo aquellos que se verán reflejados en la información financiera de las empresas. Es por ello, que nuestros estudiantes deben adquirir herramientas que les permitan comprender cómo se comportan los flujos de efectivo entrantes y salientes de una empresa, de qué manera los afecta el valor del dinero en el tiempo cuando se dan en diferentes períodos, qué impacto tienen las tasas de interés utilizadas para medir su variación, y de qué manera se deben aplicar los criterios que determinan si una alternativa o proyecto de inversión debe aceptarse o rechazarse. Esta unidad de estudio le permite a los profesionales eanistas desarrollar destrezas en el manejo del dinero a través del tiempo, el cálculo de tasas de interés y en el análisis de las implicaciones de los criterios de rentabilidad, los cuales son elementos fundamentales para la adecuada toma de decisiones financieras a través de su aplicación práctica en la solución de problemas. | S7: Interpretar datos de mercado y de los consumidores teniendo en cuenta metodologías de análisis, eficacia y rentabilidad empresarial siendo coherentes con los objetivos de la organización. Desarrollar estrategias de mercadeo integrales con base en en el análisis de mercado, tendencias, y comportamiento del consumidor para una mayor visibilidad y posicionamiento de las marcas en entornos competitivos. Diseñar estrategias de branding y creación de marcas con propósito a través de la generación de contenido atractivo que resuene con diversas audiencias y se alinee con los principios de mercadeo sostenible. Aplicar el pensamiento creativo e innovador en el desarrollo de estrategias de mercadeo mediante campañas publicitarias originales, productos innovadores, y estrategias disruptivas, con segmentación de audiencias y alianzas estratégicas para el éxito empresarial. | T7: Analiza datos de mercado y comportamiento de los consumidores a partir del uso de metodologías, lineamientos de eficacia y rentabilidad, enfocados en los objetivos organizacionales. Formula estrategias basadas en la comprensión del mercado mediante el estudio del mercado para el posicionamiento y reconocimiento de las marcas. Diseña marcas con propósito y planes de comunicación con base en en las diferentes audiencias teniendo en cuenta los principios de sostenibilidad. Desarrolla campañas publicitarias, productos innovadores y estrategias disruptivas con base en el crecimiento organizacional del mercado a partir de la creación de alianzas estratégicas, la segmentación de audiencias y el pensamiento creativo e innovador. Integra principios éticos sostenibles y de responsabilidad social en las estrategias de mercadeo teniendo en cuenta la proposición de acciones encaminadas a la creación de valor compartido y la integridad organizacional. Planifica el desarrollo de sitios web y aplicaciones digitales a través del uso de herramientas y técnicas avanzadas de diseño y desarrollo web | U7: Resuelve problemas financieros mediante el uso de los conceptos relacionados con el valor del dinero en el tiempo. | V7: Visualiza y describe las transacciones financieras en términos de flujos de efectivo entrantes y salientes | W7: Aplica los conceptos y principios de valor de dinero en el tiempo a la realidad de la organización. | X7: Calcula la tasa de interés en una operación financiera y desarrolla procesos de equivalencia entre los diferentes tipos de tasas. | Y7: Compara alternativas y toma decisiones a partir del análisis de flujos de efectivo. | Z7: X | AA7: X | AB7: X | AC7: X | AD7: X | AE7: X | AF7: X | AG7: X | AH7: X | AI7: Valor del dinero en el tiempo Tasas de interés Diagramas de flujos de efectivo Equivalencias de flujos de efectivo Indicadores de bondad económica Tablas de amortización | AJ7: LECTURA PREVIA: Agudelo, D. y Fernández, A. (2019), p. 43-71. Meza (2013), p 15-30. Gutiérrez (2012), p. 1-40. *Actividad de aprendizaje N. 1: Interés simple *Situación problémica individual. | AK7: La Unidad de estudio semestral posee cuatro cortes: Primer corte 40% Segundo corte 50% Prueba objetiva: 10% Cada corte estará distribuido así: - Talleres grupales - Controles de lectura - Investigación/Informe/Estudio de caso - Evaluación de Corte - Participación en eventos y salidas académicas - Prueba objetiva | AL7: Excel | AM7: Ingles | AN7: 0.2 | AO7: Aguilera, V. y Díaz, G. (2020). Matemáticas financieras. McGraw-Hill Interamericana. Agudelo, D. y Fernández, A. (2019) Matemáticas financieras: conceptos y aplicaciones. Bogotá: Pearson. http://www.ebooks7-24.com.bdbiblioteca.universidadean.edu.co/?il=7897 Ángel, P. Santacruz, J (2010) Decisiones financieras bajo incertidumbre. Escuela Colombiana de Ingeniería. Pearson. Broverman, S. (2015). Mathematics of investment and credit. 6th ed. ACTEX Publications. Cano, A. (2017). Matemáticas financieras, aplicada a ciencias económicas, administrativas y contables. Segunda edición. Ediciones de la U. García, J. (2008). Matemáticas financieras con ecuaciones de diferencia finita. Quinta edición. Editorial Pearson Prentice Hall. Gutiérrez, J. (2012). Matemáticas Financieras con fórmulas, calculadora financiera y Excel. Editorial ECOE.
A8: =G8&H8 -> MERCADEO Y ESTRATEGIA COMERCIALECONOMÍA DE MERCADO | B8: 2022 | C8: 2001327 | D8: AFVN0028 | E8: NUCLEAR | F8: FAFCE | G8: MERCADEO Y ESTRATEGIA COMERCIAL | H8: ECONOMÍA DE MERCADO | I8: 4 | J8: 72 | K8: 120 | L8: 192 | N8: VIRTUAL | R8: La unidad de estudios de Economía de Mercado está orientada a vincular a los estudiantes con la ciencia económica que le permita analizar el contexto económico de las organizaciones a partir de la comprensión de las generalidades y principios del sistema económico mediante de la examinación y aplicación de los conceptos esenciales del análisis microeconómico y macroeconómico. Para ello se introducen los principales temas tratados por esta ciencia, lo cual servirá como base para la profundización en áreas específicas en semestres siguientes. El punto de partida es la definición de economía, en la cual sobresale su carácter de ciencia social. Orientando el análisis económico desde un enfoque microeconómico que analiza cómo toman las decisiones los agentes económicos en mercados específicos. Y desde el enfoque macroeconómico estudiando los principales agregados macroeconómicos, las políticas macroeconómicas y el entorno internacional. | S8: Interpretar datos de mercado y de los consumidores teniendo en cuenta metodologías de análisis, eficacia y rentabilidad empresarial siendo coherentes con los objetivos de la organización. Desarrollar estrategias de mercadeo integrales con base en en el análisis de mercado, tendencias, y comportamiento del consumidor para una mayor visibilidad y posicionamiento de las marcas en entornos competitivos. Diseñar estrategias de branding y creación de marcas con propósito a través de la generación de contenido atractivo que resuene con diversas audiencias y se alinee con los principios de mercadeo sostenible. Aplicar el pensamiento creativo e innovador en el desarrollo de estrategias de mercadeo mediante campañas publicitarias originales, productos innovadores, y estrategias disruptivas, con segmentación de audiencias y alianzas estratégicas para el éxito empresarial. | T8: Analiza datos de mercado y comportamiento de los consumidores a partir del uso de metodologías, lineamientos de eficacia y rentabilidad, enfocados en los objetivos organizacionales. Formula estrategias basadas en la comprensión del mercado mediante el estudio del mercado para el posicionamiento y reconocimiento de las marcas. Diseña marcas con propósito y planes de comunicación con base en en las diferentes audiencias teniendo en cuenta los principios de sostenibilidad. Desarrolla campañas publicitarias, productos innovadores y estrategias disruptivas con base en el crecimiento organizacional del mercado a partir de la creación de alianzas estratégicas, la segmentación de audiencias y el pensamiento creativo e innovador. Integra principios éticos sostenibles y de responsabilidad social en las estrategias de mercadeo teniendo en cuenta la proposición de acciones encaminadas a la creación de valor compartido y la integridad organizacional. Planifica el desarrollo de sitios web y aplicaciones digitales a través del uso de herramientas y técnicas avanzadas de diseño y desarrollo web | U8: Comprende los principios de la ciencia económica y los fundamentos del funcionamiento de las economías de mercado modernas mediante la examinación de los conceptos y resultados prácticos esenciales del análisis microeconómico y macroeconómico y su aplicación al contexto empresarial y la sostenibilidad. | V8: Reconoce el concepto de economía, los problemas económicos y las ramas de la teoría económica. | W8: Ejemplifica contextos locales en modelos de diagrama de flujo circular y frontera de posibilidades de producción. | X8: Analiza mercados usando modelo de oferta y demanda, y las elasticidades en el ámbito empresarial. | Y8: Comprende el desempeño de la economía nacional y de otros países empleando los principales agregados macroeconómicos y estudiando los sectores de la economía como el financiero y el externo. | Z8: X | AA8: X | AB8: X | AC8: X | AD8: X | AE8: X | AF8: X | AG8: X | AH8: X | AI8: 1. Introducción a la ciencia económica y los principios de la economía 2. Modelos económicos básicos 2.1. Diagrama de Flujo Circular 2.2. Frontera de Posibilidades de Producción 3. Fundamentacion microeconómica 3.1. Tipos de mercado 3.2. Análisis de mercado: equilibrio oferta-demanda 3.3. Elasticidades de demanda y oferta 3.4. Eficiencia: excedente del consumidor y productor 3.5. Microeconomía y medio ambiente: principios básicos 4. Fundamentos de macroeconomía 4.1. Agregados macroeconómicos: medición e implicaciones 4.1.1. PIB, crecimiento, productividad 4.1.2. IPC e inflación 4.1.3. Desempleo y Mercado Laboral 4.1.4. Pobreza y desigualdad 4.2. El banco central y el sistema financiero: dinero e interés 4.3. Ventaja comparativa, tasas de cambio y el sector externo 4.4. Introducción a la política económica | AJ8: Lecturas con preguntas de reflexión Discusiones en grupo Ejercicios aplicados Videos Ludificación | AK8: La Unidad de estudio semestral posee cuatro cortes: Primer corte 20% Segundo corte 20% Tercer corte 30% Cuarto corte 30% Cada corte estará distribuido así: - Talleres grupales - Controles de lectura - Investigación/Informe/Estudio de caso - Evaluación de Corte - Participación en eventos y salidas académicas | AL8: Bases de datos • Banco República: www.banrep.gov.co • DANE: www.dane.gov.co • Banco Mundial: https://datos.bancomundial.org/ Excel | AM8: Ingles | AN8: 0.1 | AO8: Mankiw, G. (2020). Principios de Economía. Cengage Learning. 330M278 Cárdenas, M. (2020). Introducción a la Economía colombiana. Alpha Editorial. 330.9861C266 Banco de la República. (1998). Introducción al Análisis Económico. Siglo del Hombre Editores. 330B213 Samuelson, P. y Nordhaus, W. (2010). Economía con aplicación a Latinoamérica. McGGraw- Hill Education. 330S197ec Sowell, Thomas. (2013). Economía Básica. Deusto. | AP8: Nieto, Mauricio. (2023). Fundamentos de Economía: una aplicación de las teorías y su análisis crítico. ECOE Ediciones. Krugman, P., Wells, R. y Olney, M. (2010) Fundamentos de Economía. Editorial Reverté. 330 K943 Parkin, M. (2018) Economía. McGraw Hill. 330P237 Samuelson, P. y Nordhaus, W. (2019). Economía con Aplicaciones. McGGraw- Hill Podcasts y RRSS: Economía de a Pie (Bancolombia) Investigaciones Económicas (Corficolombiana) Economicast (El Tiempo) Economía para la pipol Tuttle Twins (caricatura) Blogs y sitios web: https://fee.org/articles/topics/Economics https://www.project-syndicate.org/section/economics https://www.imf.org/es/Blogs
A9: =G9&H9 -> MERCADEO Y ESTRATEGIA COMERCIALMIND GREEN CONS: EXPL LA TOMA DE DECI | B9: 2024 | C9: 2001327 | D9: AFVN0082 | E9: NUCLEAR | F9: FAFCE | G9: MERCADEO Y ESTRATEGIA COMERCIAL | H9: MIND GREEN CONS: EXPL LA TOMA DE DECI | I9: 3 | J9: 54 | K9: 90 | L9: 144 | N9: VIRTUAL | R9: El propósito de este curso es explorar y comprender el comportamiento del consumidor verde, analizando los factores que influyen en la toma de decisiones de compra sostenibles. Los estudiantes aprenderán a identificar y aplicar estrategias que promuevan el consumo responsable, utilizando enfoques multidisciplinarios que abarcan la psicología del consumidor, la sostenibilidad y el marketing verde. Esta unidad de estudio está diseñada para equipar a los estudiantes con las herramientas y conocimientos necesarios para influir positivamente en el mercado, promoviendo prácticas de consumo que favorezcan la conservación del medio ambiente y el bienestar social. | S9: Interpretar datos de mercado y de los consumidores teniendo en cuenta metodologías de análisis, eficacia y rentabilidad empresarial siendo coherentes con los objetivos de la organización. Desarrollar estrategias de mercadeo integrales con base en en el análisis de mercado, tendencias, y comportamiento del consumidor para una mayor visibilidad y posicionamiento de las marcas en entornos competitivos. Diseñar estrategias de branding y creación de marcas con propósito a través de la generación de contenido atractivo que resuene con diversas audiencias y se alinee con los principios de mercadeo sostenible. Aplicar el pensamiento creativo e innovador en el desarrollo de estrategias de mercadeo mediante campañas publicitarias originales, productos innovadores, y estrategias disruptivas, con segmentación de audiencias y alianzas estratégicas para el éxito empresarial. | T9: Analiza datos de mercado y comportamiento de los consumidores a partir del uso de metodologías, lineamientos de eficacia y rentabilidad, enfocados en los objetivos organizacionales. Formula estrategias basadas en la comprensión del mercado mediante el estudio del mercado para el posicionamiento y reconocimiento de las marcas. Diseña marcas con propósito y planes de comunicación con base en en las diferentes audiencias teniendo en cuenta los principios de sostenibilidad. Desarrolla campañas publicitarias, productos innovadores y estrategias disruptivas con base en el crecimiento organizacional del mercado a partir de la creación de alianzas estratégicas, la segmentación de audiencias y el pensamiento creativo e innovador. Integra principios éticos sostenibles y de responsabilidad social en las estrategias de mercadeo teniendo en cuenta la proposición de acciones encaminadas a la creación de valor compartido y la integridad organizacional. Planifica el desarrollo de sitios web y aplicaciones digitales a través del uso de herramientas y técnicas avanzadas de diseño y desarrollo web | U9: Analiza las teorías del comportamiento del consumidor y los factores internos y externos que influyen en sus decisiones de compra, aplicando metodologías de investigación para la comprensión de su comportamiento. | V9: Identifica y analiza los factores psicológicos, sociales, culturales y económicos que motivan a los consumidores por las opciones sostenibles en el mercado | W9: Aplica teorías y modelos de la psicología del consumidor para entender mejor cómo se forman las actitudes y preferencias hacia productos verdes. | X9: Implementa métodos de investigación para estudiar el comportamiento del consumidor verde, incluyendo encuestas, entrevistas y análisis de datos, con el fin de obtener Insights accionables. | Y9: Desarrolla y evalúa estrategias de marketing verde que promuevan el consumo responsable, utilizando un enfoque multidisciplinario que abarque la sostenibilidad ambiental, las prácticas empresariales responsables y las técnicas avanzadas de marketing. | Z9: X | AB9: X | AC9: X | AE9: X | AG9: X | AH9: X | AI9: 1. Introducción al consumo verde sostenible 1.1. Conceptos básicos del consumo verde 1.2. Importancia del consumo verde 1.3. Perfiles de consumidores verdes 2. Factores psicológicos y sociales en la toma de decisiones del consumidor verde. 2.1. Factores Psicológicos 2.2. Factores sociales y culturales 3. Estrategias del marketing verde 3.1. Fundamentos del marketing verde 3.2. Desarrollo de estrategias de marketing verde 3.3. Ejecución de campañas de marketing verde 4. Análisis de datos y herramientas de investigación del Consumidor 4.1. Métodos de investigación cuantitativa y cualitativa 4.2. Herramientas de análisis de datos 4.3. Evaluación y uso de Insigths de consumidores 5. Implementación de prácticas sostenibles en las empresas 5.1. Integración de la sostenibilidad en la estrategia empresarial 5.2. Certificaciones y normas ambientales 5.3. Responsabilidad social corporativa (RSC) 6. Medición y evaluación del impacto del consumo verde 6.1. Indicadores y métricas de sostenibilidad 6.2. Evaluación del retorno de la inversión (ROI) en iniciativas verdes 6.3. Comunicación de resultados y mejores prácticas | AJ9: Aprendizaje Colaborativo Aprendizaje Autónomo Aprendizaje basado en proyectos Estudio de Casos Aprendizaje basado en retos Lecturas Talleres | AK9: Evaluación Primer Hito 15% Trabajo segundo Hito 20% Trabajo Tercer Hito 20% Trabajo Final Hito 4 20% Encuentro Final 25% | AL9: Plataforma de Canvas Bases de Datos de la Universidad Ean Sitios Web especializados Microsoft Office | AM9: Inglés | AN9: 0.4 | AO9: Griskevicius, V., Tybur, J. M., & Van den Bergh, B. (2010). Going Green to Be Seen: Status, Reputation, and Conspicuous Conservation. Journal of Personality and Social Psychology. Ottman, J. A. (2017). The New Rules of Green Marketing: Strategies, Tools, and Inspiration for Sustainable Branding. Routledge. Peattie, K. (2010). Green Marketing. SAGE Publications. Tanner, C., & Kast, S. W. (2003). Promoting Sustainable Consumption: Determinants of Green Purchases by Swiss Consumers. Psychology & Marketing. Thøgersen, J. (2005). Psychological Determinants of Green Consumer Choice. Oxford University Press. | AP9: Gifford, R. (2011). The Dragons of Inaction: Psychological Barriers That Limit Climate Change Mitigation and Adaptation. American Psychologist. White, K., Habib, R., & Hardisty, D. J. (2019). How to SHIFT Consumer Behaviors to be More Sustainable: A Literature Review and Guiding Framework. Journal of Marketing.
